<?xml version="1.0"?>
<robot xmlns:xacro="http://www.ros.org/wiki/xacro">

  <xacro:macro name="igus_5DOF_SV" params="parent prefix *origin">
    <joint name="linear_joint" type="fixed">
      <parent link="${parent}" />
      <child link = "linear_link" />
      <origin xyz="0.0 0.0 0.375" rpy="-1.57 0.0 1.57" />
      <axis xyz="0 0 1"/>
      <limit effort="30" velocity="1.0" />
    </joint>

    <joint name="arm_joint" type="prismatic">
      <parent link="linear_link" />
      <child link = "igus_base_link" />
      <origin xyz="0.0 -0.36 -0.0" rpy="3.14 0 1.57" />
      <axis xyz="-1 0 0"/>
      <limit effort="100" velocity="0.025" lower = "0.0" upper = "0.95"/>
      <dynamics damping="1000.0"/>
    </joint>

    <link name="linear_link">
    <visual>
      <origin xyz="0.0 0.0 0.0" rpy="0 0 0"/>
      <geometry>
          <mesh filename="package://neo_mp_400/robot_model/mp_400/meshes/vertical_axis.dae"  scale="0.001 0.001 0.001"/>
      </geometry>
    </visual>
    <collision>
      <origin xyz="0.0 0.0 0.0" rpy="0 0 0"/>
      <geometry>
          <mesh filename="package://neo_mp_400/robot_model/mp_400/meshes/vertical_axis.dae"  scale="0.001 0.001 0.001"/>
      </geometry>
    </collision>
     <inertial>
      <origin xyz="0.0 0.0 0.0" rpy="0 0 0"/>
      <mass value="30.0"/>
      <inertia ixx="0.05" ixy="0.05" ixz="0.05" iyy="0.05" iyz="0.05" izz="0.05"/>
    </inertial>
  </link>
   
  <link name="igus_base_link">
    <visual>
    <origin rpy="0 0 0" xyz="0 0 0"/>
      <geometry>
          <mesh filename="package://neo_mp_400/robot_model/mp_400/meshes/Joint0.dae"  scale="0.001 0.001 0.001"/>
        </geometry>
    </visual>
    <collision>
      <origin xyz="0 0 0" rpy="0 0 0" />
      <geometry>
          <mesh filename="package://neo_mp_400/robot_model/mp_400/meshes/Joint0.dae" scale="0.001 0.001 0.001"/>
        </geometry>
    </collision>
    <inertial>
      <origin xyz="0.0 0.0 0.0" rpy="0 0 0"/>
      <mass value="5.0"/>
      <inertia ixx="0.1045" ixy="-0.000460884801" ixz="0.000101130383"
                    iyy="0.105" iyz="0.002941" izz="0.01284"/>
    </inertial>
  </link>
  <link name="link1">
    <visual>
    <origin rpy="0 0 0" xyz="0.0 0 0.0"/>
      <geometry>
          <mesh filename="package://neo_mp_400/robot_model/mp_400/meshes/Joint1.dae"  scale="0.001 0.001 0.001"/>
        </geometry>
    </visual>
    <collision>
      <origin xyz="0 0 0" rpy="0 0 0" />
      <geometry>
          <mesh filename="package://neo_mp_400/robot_model/mp_400/meshes/Joint1.dae" scale="0.001 0.001 0.001"/>
        </geometry>
    </collision>
<inertial>
      <origin xyz="0.0 0.0 0.0" rpy="0 0 0"/>
      <mass value="5.0"/>
      <inertia ixx="0.1045" ixy="-0.000460884801" ixz="0.000101130383"
                    iyy="0.105" iyz="0.002941" izz="0.01284"/>
    </inertial>
  </link>
  <link name="link2">
    <visual>
    <origin rpy="0 0 0" xyz="0.0 0 0.0"/>
      <geometry>
          <mesh filename="package://neo_mp_400/robot_model/mp_400/meshes/Joint2.dae"  scale="0.001 0.001 0.001"/>
        </geometry>
    </visual>
    <collision>
      <origin xyz="0 0 0" rpy="0 0 0" />
      <geometry>
          <mesh filename="package://neo_mp_400/robot_model/mp_400/meshes/Joint2.dae" scale="0.001 0.001 0.001"/>
        </geometry>
    </collision>
<inertial>
      <origin xyz="0.0 0.0 0.0" rpy="0 0 0"/>
      <mass value="5.0"/>
      <inertia ixx="0.1045" ixy="-0.000460884801" ixz="0.000101130383"
                    iyy="0.105" iyz="0.002941" izz="0.01284"/>
    </inertial>
  </link>
  <link name="link3">
    <visual>
    <origin rpy="0 0 0" xyz="0.0 0 0"/>
      <geometry>
          <mesh filename="package://neo_mp_400/robot_model/mp_400/meshes/Joint3.dae"  scale="0.001 0.001 0.001"/>
        </geometry>
    </visual>
    <collision>
      <origin xyz="0 0 0" rpy="0 0 0" />
      <geometry>
          <mesh filename="package://neo_mp_400/robot_model/mp_400/meshes/Joint3.dae" scale="0.001 0.001 0.001"/>
        </geometry>
    </collision>
  </link>
  <link name="link4">
    <visual>
    <origin rpy="0 0 0" xyz="0.0 0 0.0"/>
      <geometry>
          <mesh filename="package://neo_mp_400/robot_model/mp_400/meshes/Joint4.dae"  scale="0.001 0.001 0.001"/>
        </geometry>
    </visual>
    <collision>
      <origin xyz="0 0 0" rpy="0 0 0" />
      <geometry>
          <mesh filename="package://neo_mp_400/robot_model/mp_400/meshes/Joint4.dae" scale="0.001 0.001 0.001"/>
        </geometry>
    </collision>
  </link>
  <link name="link5">
    <visual>
    <origin rpy="0 0 0" xyz="0 0 -0.0"/>
      <geometry>
          <mesh filename="package://neo_mp_400/robot_model/mp_400/meshes/Joint5.dae"  scale="0.001 0.001 0.001"/>
        </geometry>
    </visual>
    <collision>
      <origin xyz="0 0 0" rpy="0 0 -0.0" />
      <geometry>
          <mesh filename="package://neo_mp_400/robot_model/mp_400/meshes/Joint5.dae" scale="0.001 0.001 0.001"/>
        </geometry>
    </collision>
  </link>
  <link name="link6">
    <visual>
      <origin rpy="0.0 0 0" xyz="0 0 0"/>
      <geometry>
        <cylinder length="0.03" radius="0.035"/>
      </geometry>
    </visual>
    <collision>
      <origin xyz="0 0 0" rpy="0 0 -0.0" />
      <geometry>
        <cylinder length="0.03" radius="0.035"/>
        </geometry>
    </collision>
  </link>
  <joint name="joint1" type="revolute">
    <axis xyz="0 0 1"/>
    <parent link="igus_base_link"/>
    <child link="link1"/>
    <origin rpy="0 0 0" xyz="-0.05 0 0.185"/>
      <limit effort="100" velocity="1.0" lower = "-2.53" upper = "2.53"/>
    <joint_properties damping="0.0" friction="0.0"/>
  </joint>
 <joint name="joint2" type="revolute">
    <axis xyz="0 1 0"/>
    <parent link="link1"/>
    <child link="link2"/>
    <origin rpy="0 0 0" xyz="0 0 0.145"/>
    <limit effort="100" lower="-0.785398" upper="1.22173" velocity="5"/>
    <dynamics damping="15.0" friction="11"/>
    <dynamics damping="100.0"/>
  </joint>
  <joint name="joint3" type="revolute">
    <axis xyz="0 -1 0"/>
    <parent link="link2"/>
    <child link="link3"/>
    <origin rpy="0 1.57079632679 0" xyz="0 0 0.350"/>
    <limit effort="100" lower="-1.5708" upper="2.00713" velocity="5"/>
    <dynamics damping="15.0" friction="11"/>
  </joint>
  <joint name="joint4" type="revolute">
    <axis xyz="0 -1 0"/>
    <parent link="link3"/>
    <child link="link4"/>
    <origin rpy="0 0 0" xyz="0 0 0.270"/>
    <limit effort="100" lower="-0.523599" upper="2.0944" velocity="5"/>
    <dynamics damping="15.0" friction="11"/>
  </joint>
  <joint name="joint5" type="revolute">
    <axis xyz="0 0 1"/>
    <parent link="link4"/>
    <child link="link5"/>
    <origin rpy="0 0 0" xyz="0 0 0.190"/>
    <limit effort="100" lower="-0.174533" upper="0.174533" velocity="5"/>
    <dynamics damping="15.0" friction="11"/>
  </joint>
 <joint name="joint6" type="revolute">
    <axis xyz="0 0 1"/>
    <parent link="link5"/>
    <child link="link6"/>
    <origin rpy="0 1.57 0" xyz="-0.04 0 0.04"/>
      <limit effort="100" velocity="1.0" lower = "-3.14" upper = "3.14"/>
    <joint_properties damping="0.0" friction="0.0"/>
  </joint> 

    <transmission name="tran_prismatic">
    <type>transmission_interface/SimpleTransmission</type>
    <joint name="arm_joint">
      <hardwareInterface>hardware_interface/VelocityJointInterface</hardwareInterface>
    </joint>
    <actuator name="tran_prismatic_motor">
      <mechanicalReduction>15</mechanicalReduction>
    </actuator>
  </transmission>

  <transmission name="tran_roll">
    <type>transmission_interface/SimpleTransmission</type>
    <joint name="joint1">
      <hardwareInterface>hardware_interface/VelocityJointInterface</hardwareInterface>
    </joint>
    <actuator name="tran_roll_motor">
      <mechanicalReduction>50</mechanicalReduction>
    </actuator>
  </transmission>

  <transmission name="tran_1">
    <type>transmission_interface/SimpleTransmission</type>
    <joint name="joint2">
      <hardwareInterface>hardware_interface/VelocityJointInterface</hardwareInterface>
    </joint>
    <actuator name="tran_1_motor">
      <mechanicalReduction>50</mechanicalReduction>
    </actuator>
  </transmission>

   <transmission name="tran_2">
    <type>transmission_interface/SimpleTransmission</type>
    <joint name="joint3">
      <hardwareInterface>hardware_interface/VelocityJointInterface</hardwareInterface>
    </joint>
    <actuator name="tran_2_motor">
      <mechanicalReduction>-38</mechanicalReduction>
    </actuator>
  </transmission>

   <transmission name="tran_3">
    <type>transmission_interface/SimpleTransmission</type>
    <joint name="joint4">
      <hardwareInterface>hardware_interface/VelocityJointInterface</hardwareInterface>
    </joint>
    <actuator name="tran_3_motor">
      <mechanicalReduction>-38</mechanicalReduction>
    </actuator>
  </transmission>

   <transmission name="tran_4">
    <type>transmission_interface/SimpleTransmission</type>
    <joint name="joint5">
      <hardwareInterface>hardware_interface/VelocityJointInterface</hardwareInterface>
    </joint>
    <actuator name="tran_4_motor">
      <mechanicalReduction>-28</mechanicalReduction>
    </actuator>
  </transmission>

  <transmission name="tran_5">
    <type>transmission_interface/SimpleTransmission</type>
    <joint name="joint6">
      <hardwareInterface>hardware_interface/VelocityJointInterface</hardwareInterface>
    </joint>
    <actuator name="tran_5_motor">
      <mechanicalReduction>32</mechanicalReduction>
    </actuator>
  </transmission>
    </xacro:macro> 
 
</robot>

